Workbook

Sheet Report
A1: Which products and services are growing?
A2: SME sample businesses · SAMPLE DATA (invented) · The Fourth Sheet
A3: Period: April 2026 · Data status: Mar 2026 locked · Apr 2026 locked · Oct 2026 incomplete (data retrieved 2pm, Tue 6 Oct 2026)
A5: Revenue, gross margin and growth (year on year) by product or service line over 24 months. Pick a line and every number, chart and note follows it.
A7: Trades
A8: Gross margin, not profit
A9: Gross margin is not profit. Job gross margin = revenue less materials, subcontractors and technician time charged to the job at $68 an hour (wages and all on-costs). Not included: technician time not charged to any job (travel, training, waiting), and overheads (office wages, marketing, vehicles, rent, insurance, IT, depreciation, interest). Profit is what's left after those. Wages always include all on-costs: super, payroll tax, workers' compensation insurance and leave.
A11: From gross margin to profit
A12: April's jobs made $68,843 gross margin (41.7%). Technician time not charged to jobs took $6,456 and overheads $59,290, leaving $3,097 profit before tax (1.9% of revenue). To cover overheads, jobs need a 39.8% gross margin on average. (Workings sheet: "From gross margin to profit".)
A14: Line: All
A15: Headline number | B15: Value | C15: Compared with
A16: April against April last year | B16: =Workings!B27 | C16: $164,987 against $124,705
A17: Year to date (Jul to Apr 2026) | B17: =Workings!B35 | C17: same period last year: not in the data
A18: Gross margin, year to date | B18: =Workings!B43 | C18: $605,185 before overheads
A20: What it shows
A21: Revenue is $1,610,581 this financial year to date (Jul to Apr 2026). Maintenance contracts make the highest gross margin (59.5%); Installations the lowest (28.4%). The business needs 39.8% gross margin just to cover overheads.
A23: What you'd do about it
A24: Installations: 28.4% gross margin, 6.6 points under the 35.0% target: about $66,763 on $1,011,500 of revenue this financial year to date. It's below the 39.8% needed to cover overheads, too. Maintenance contracts: 59.5% gross margin, 24.5 points over the 35.0% target ($87,069 ahead on $355,300 this financial year to date).
A26: Line: Maintenance contracts
A27: Headline number | B27: Value | C27: Compared with
A28: April against April last year | B28: =Workings!B51 | C28: $37,500 against $27,930
A29: Year to date (Jul to Apr 2026) | B29: =Workings!B59 | C29: same period last year: not in the data
A30: Gross margin, year to date | B30: =Workings!B67 | C30: $211,424 before overheads
A32: What it shows
A33: Maintenance contracts brought in $355,300 this financial year to date, at a 59.5% gross margin (above the 37.6% overall).
A35: What you'd do about it
A36: Maintenance contracts: 59.5% gross margin, 24.5 points over the 35.0% target ($87,069 ahead on $355,300 this financial year to date).
A38: Line: Installations
A39: Headline number | B39: Value | C39: Compared with
A40: April against April last year | B40: =Workings!B75 | C40: $104,400 against $74,900
A41: Year to date (Jul to Apr 2026) | B41: =Workings!B83 | C41: same period last year: not in the data
A42: Gross margin, year to date | B42: =Workings!B91 | C42: $287,262 before overheads
A44: What it shows
A45: Installations brought in $1,011,500 this financial year to date, at a 28.4% gross margin (below the 37.6% overall).
A47: What you'd do about it
A48: Installations: 28.4% gross margin, 6.6 points under the 35.0% target: about $66,763 on $1,011,500 of revenue this financial year to date. It's below the 39.8% needed to cover overheads, too.
A50: Line: Call-outs and repairs
A51: Headline number | B51: Value | C51: Compared with
A52: April against April last year | B52: =Workings!B99 | C52: $23,087 against $21,875
A53: Year to date (Jul to Apr 2026) | B53: =Workings!B107 | C53: same period last year: not in the data
...

Sheet Workings
A1: How each number is worked out
A2: SME sample businesses · SAMPLE DATA (invented) · The Fourth Sheet
A3: Period: April 2026 · Data status: Mar 2026 locked · Apr 2026 locked · Oct 2026 incomplete (data retrieved 2pm, Tue 6 Oct 2026)
A5: From gross margin to profit, April 2026
A6: Gross margin on the work − time not charged − overheads = profit before tax
B7: Apr 2026
A8: Gross margin on jobs | B8: 68843
A9: Technician wages and on-costs | B9: 54600
A10: Technician time charged to jobs (at cost) | B10: 48144
A11: Technician time not charged to jobs | B11: =B9-B10
A12: Gross profit (the P&L) | B12: =B8-B11
A13: Overheads (operating expenses, depreciation, interest) | B13: 59290
A14: Profit before tax (the P&L) | B14: =B12-B13
A15: Revenue | B15: 164987
A16: Gross margin on jobs, % | B16: =B8/B15
A17: Profit before tax, % of revenue | B17: =B14/B15
A18: Gross margin jobs need just to cover overheads and time not charged | B18: =(B11+B13)/B15
A19: Ties to the April 2026 P&L (locked). Wages always include all on-costs: super, payroll tax, workers' compensation insurance and leave.
A22: All lines: April against April last year
A23: April 2026 ÷ April 2025 − 1 (year on year)
B24: Apr
A25: Revenue, Apr 2026 | B25: 164987
A26: Revenue, Apr 2025 | B26: 124705
A27: Growth | B27: =B25/B26-1
A30: All lines: year to date
A31: Financial year to date. Not available: the data starts October 2024.
B32: Year to date
A33: Revenue, year to date (Jul to Apr 2026) | B33: 1610581
A34: Gross margin, year to date | B34: 605185
A35: Gross margin %, year to date | B35: =B34/B33
A38: All lines: year to date
A39: Financial year to date. Not available: the data starts October 2024.
B40: Year to date
A41: Revenue, year to date (Jul to Apr 2026) | B41: 1610581
A42: Gross margin, year to date | B42: 605185
A43: Gross margin %, year to date | B43: =B42/B41
A46: Maintenance contracts: April against April last year
A47: April 2026 ÷ April 2025 − 1 (year on year)
B48: Apr
A49: Revenue, Apr 2026 | B49: 37500
...

Sheet Data Trades
A1: Data Trades
A2: SME sample businesses · SAMPLE DATA (invented) · The Fourth Sheet
A3: Period: April 2026 · Data status: Mar 2026 locked · Apr 2026 locked · Oct 2026 incomplete (data retrieved 2pm, Tue 6 Oct 2026)
A5: Line | B5: Month | C5: Status | D5: Revenue | E5: Direct cost | F5: Gross margin | G5: Gross margin %
A6: All | B6: Oct 24 | C6: Locked | D6: 171009 | E6: 114334 | F6: =D6-E6 | G6: =IF(D6=0,"",F6/D6)
A7: All | B7: Nov 24 | C7: Locked | D7: 179474 | E7: 113016 | F7: =D7-E7 | G7: =IF(D7=0,"",F7/D7)
A8: All | B8: Dec 24 | C8: Locked | D8: 143156 | E8: 85316 | F8: =D8-E8 | G8: =IF(D8=0,"",F8/D8)
A9: All | B9: Jan 25 | C9: Locked | D9: 140909 | E9: 80742 | F9: =D9-E9 | G9: =IF(D9=0,"",F9/D9)
A10: All | B10: Feb 25 | C10: Locked | D10: 160943 | E10: 102348 | F10: =D10-E10 | G10: =IF(D10=0,"",F10/D10)
A11: All | B11: Mar 25 | C11: Locked | D11: 135082 | E11: 85752 | F11: =D11-E11 | G11: =IF(D11=0,"",F11/D11)
A12: All | B12: Apr 25 | C12: Locked | D12: 124705 | E12: 76808 | F12: =D12-E12 | G12: =IF(D12=0,"",F12/D12)
A13: All | B13: May 25 | C13: Locked | D13: 129816 | E13: 83700 | F13: =D13-E13 | G13: =IF(D13=0,"",F13/D13)
A14: All | B14: Jun 25 | C14: Locked | D14: 164113 | E14: 97584 | F14: =D14-E14 | G14: =IF(D14=0,"",F14/D14)
A15: All | B15: Jul 25 | C15: Locked | D15: 186760 | E15: 120326 | F15: =D15-E15 | G15: =IF(D15=0,"",F15/D15)
A16: All | B16: Aug 25 | C16: Locked | D16: 139164 | E16: 78258 | F16: =D16-E16 | G16: =IF(D16=0,"",F16/D16)
A17: All | B17: Sep 25 | C17: Locked | D17: 128255 | E17: 80054 | F17: =D17-E17 | G17: =IF(D17=0,"",F17/D17)
... A81: Call-outs and repairs | B81: Apr 26 | C81: Locked | D81: 23087 | E81: 12970 | F81: =D81-E81 | G81: =IF(D81=0,"",F81/D81)

Sheet Year to date Trades
A1: Year to date Trades
A2: SME sample businesses · SAMPLE DATA (invented) · The Fourth Sheet
A3: Period: April 2026 · Data status: Mar 2026 locked · Apr 2026 locked · Oct 2026 incomplete (data retrieved 2pm, Tue 6 Oct 2026)
A5: Line | B5: Year to date | C5: Same period last year | D5: Growth | E5: Gross margin $ | F5: Gross margin %
A6: Maintenance contracts | B6: 355300 | D6: =IF(C6=0,"",B6/C6-1) | E6: 211424 | F6: =IF(B6=0,"",E6/B6)
A7: Installations | B7: 1011500 | D7: =IF(C7=0,"",B7/C7-1) | E7: 287262 | F7: =IF(B7=0,"",E7/B7)
A8: Call-outs and repairs | B8: 243781 | D8: =IF(C8=0,"",B8/C8-1) | E8: 106499 | F8: =IF(B8=0,"",E8/B8)
A9: Total | B9: 1610581 | D9: =IF(C9=0,"",B9/C9-1) | E9: 605185 | F9: =IF(B9=0,"",E9/B9)

Sheet Data Services
A1: Data Services
A2: SME sample businesses · SAMPLE DATA (invented) · The Fourth Sheet
A3: Period: April 2026 · Data status: Mar 2026 locked · Apr 2026 locked · Oct 2026 incomplete (data retrieved 2pm, Tue 6 Oct 2026)
A5: Line | B5: Month | C5: Status | D5: Revenue | E5: Direct cost | F5: Gross margin | G5: Gross margin %
A6: All | B6: Oct 24 | C6: Locked | D6: 94520 | E6: 35320 | F6: =D6-E6 | G6: =IF(D6=0,"",F6/D6)
A7: All | B7: Nov 24 | C7: Locked | D7: 108140 | E7: 40040 | F7: =D7-E7 | G7: =IF(D7=0,"",F7/D7)
A8: All | B8: Dec 24 | C8: Locked | D8: 114895 | E8: 42940 | F8: =D8-E8 | G8: =IF(D8=0,"",F8/D8)
A9: All | B9: Jan 25 | C9: Locked | D9: 88250 | E9: 33260 | F9: =D9-E9 | G9: =IF(D9=0,"",F9/D9)
A10: All | B10: Feb 25 | C10: Locked | D10: 111010 | E10: 42820 | F10: =D10-E10 | G10: =IF(D10=0,"",F10/D10)
A11: All | B11: Mar 25 | C11: Locked | D11: 77175 | E11: 31940 | F11: =D11-E11 | G11: =IF(D11=0,"",F11/D11)
A12: All | B12: Apr 25 | C12: Locked | D12: 63970 | E12: 25520 | F12: =D12-E12 | G12: =IF(D12=0,"",F12/D12)
A13: All | B13: May 25 | C13: Locked | D13: 95555 | E13: 36100 | F13: =D13-E13 | G13: =IF(D13=0,"",F13/D13)
A14: All | B14: Jun 25 | C14: Locked | D14: 90220 | E14: 35380 | F14: =D14-E14 | G14: =IF(D14=0,"",F14/D14)
A15: All | B15: Jul 25 | C15: Locked | D15: 86320 | E15: 32820 | F15: =D15-E15 | G15: =IF(D15=0,"",F15/D15)
A16: All | B16: Aug 25 | C16: Locked | D16: 61475 | E16: 21360 | F16: =D16-E16 | G16: =IF(D16=0,"",F16/D16)
A17: All | B17: Sep 25 | C17: Locked | D17: 59535 | E17: 20280 | F17: =D17-E17 | G17: =IF(D17=0,"",F17/D17)
... A81: Training | B81: Apr 26 | C81: Locked | D81: 5200 | E81: 960 | F81: =D81-E81 | G81: =IF(D81=0,"",F81/D81)

Sheet Year to date Services
A1: Year to date Services
A2: SME sample businesses · SAMPLE DATA (invented) · The Fourth Sheet
A3: Period: April 2026 · Data status: Mar 2026 locked · Apr 2026 locked · Oct 2026 incomplete (data retrieved 2pm, Tue 6 Oct 2026)
A5: Line | B5: Year to date | C5: Same period last year | D5: Growth | E5: Gross margin $ | F5: Gross margin %
A6: Projects | B6: 509230 | D6: =IF(C6=0,"",B6/C6-1) | E6: 313630 | F6: =IF(B6=0,"",E6/B6)
A7: Retainers | B7: 235000 | D7: =IF(C7=0,"",B7/C7-1) | E7: 155200 | F7: =IF(B7=0,"",E7/B7)
A8: Training | B8: 70600 | D8: =IF(C8=0,"",B8/C8-1) | E8: 52660 | F8: =IF(B8=0,"",E8/B8)
A9: Total | B9: 814830 | D9: =IF(C9=0,"",B9/C9-1) | E9: 521490 | F9: =IF(B9=0,"",E9/B9)
