Workbook

Sheet The fourth sheet
A1: The fourth sheet: September 2026 against August 2026
A2: Sample Advisory Pty Ltd · SAMPLE DATA (invented) · The Fourth Sheet
A3: Data status: Sep 2026 locked · Aug 2026 locked · Oct 2026 incomplete (data retrieved 2pm, Tue 6 Oct 2026)
A5: Headline number | B5: Sep 2026 | C5: Aug 2026 | D5: Change
A6: Consultant utilisation | B6: =Workings!B13 | C6: =Workings!C13 | D6: =B6-C6
A7: Revenue per billable hour | B7: =Workings!B21 | C7: =Workings!C21 | D7: =B7-C7
A8: Unbilled work + unpaid invoices | B8: =Workings!B30 | C8: =Workings!C30 | D8: =B8-C8
A11: Margin on each client engagement, September 2026 work only
A12: September's revenue less contractors and consultant time at $60/hour. Not the whole engagement to date. One 40.0% target for every engagement for now.
B13: Margin % | C13: Contribution $
A14: Power BI basics | B14: =Workings!B43 | C14: =Workings!B42
A15: Retail pricing review | B15: =Workings!B55 | C15: =Workings!B54
A16: Agribusiness CFO support | B16: =Workings!B67 | C16: =Workings!B66
A17: Health charity board pack | B17: =Workings!B79 | C17: =Workings!B78
A18: Construction firm finance | B18: =Workings!B91 | C18: =Workings!B90
A19: Excel for managers | B19: =Workings!B103 | C19: =Workings!B102
A20: Dental group reporting | B20: =Workings!B115 | C20: =Workings!B114
A21: Manufacturer process mapping | B21: =Workings!B127 | C21: =Workings!B126
A22: Logistics systems rollout | B22: =Workings!B139 | C22: =Workings!B138
A23: Hospitality payroll | B23: =Workings!B151 | C23: =Workings!B150
A24: Target | B24: 0.4

Sheet Profit and loss
A1: Profit and loss, September 2026
A2: Sample Advisory Pty Ltd · SAMPLE DATA (invented) · The Fourth Sheet
A3: Data status: Sep 2026 locked · Aug 2026 locked · Oct 2026 incomplete (data retrieved 2pm, Tue 6 Oct 2026)
A4: $ | B4: Sep 2026 | C4: Aug 2026 | D4: Change
A5: Revenue
A6: Projects (hours worked) | B6: 85950 | C6: 75740 | D6: =B6-C6
A7: Retainers | B7: 32500 | C7: 32500 | D7: =B7-C7
A8: Training | B8: 13400 | C8: 6400 | D8: =B8-C8
A9: Total revenue | B9: =SUM(B6:B8) | C9: =SUM(C6:C8) | D9: =B9-C9
A10: Cost of sales
A11: Consultant salaries (incl. super) | B11: -46500 | C11: -46500 | D11: =B11-C11
A12: Contractors | B12: -8500 | C12: -6900 | D12: =B12-C12
A13: Total cost of sales | B13: =SUM(B11:B12) | C13: =SUM(C11:C12) | D13: =B13-C13
A14: Gross profit | B14: =B9+B13 | C14: =C9+C13 | D14: =B14-C14
A15: Operating expenses
A16: Management and admin wages | B16: -24000 | C16: -24000 | D16: =B16-C16
A17: Marketing and business development | B17: -5800 | C17: -6500 | D17: =B17-C17
A18: Rent and occupancy | B18: -8000 | C18: -8000 | D18: =B18-C18
A19: IT and software | B19: -4500 | C19: -4500 | D19: =B19-C19
A20: Professional indemnity insurance | B20: -2500 | C20: -2500 | D20: =B20-C20
A21: Travel | B21: -1800 | C21: -2600 | D21: =B21-C21
A22: Other overheads | B22: -3300 | C22: -3300 | D22: =B22-C22
A23: Total operating expenses | B23: =SUM(B16:B22) | C23: =SUM(C16:C22) | D23: =B23-C23
A24: EBITDA | B24: =B14+B23 | C24: =C14+C23 | D24: =B24-C24
A25: Depreciation | B25: -2000 | C25: -2000 | D25: =B25-C25
A26: Interest | B26: -240 | C26: -250 | D26: =B26-C26
A27: Profit before tax | B27: =B24+B25+B26 | C27: =C24+C25+C26 | D27: =B27-C27
A28: Income tax provision (25%) | B28: -6178 | C28: -1898 | D28: =B28-C28
A29: Net profit after tax | B29: =B27+B28 | C29: =C27+C28 | D29: =B29-C29

Sheet Balance sheet
A1: Balance sheet at 30 September 2026
A2: Sample Advisory Pty Ltd · SAMPLE DATA (invented) · The Fourth Sheet
A3: Data status: Sep 2026 locked · Aug 2026 locked · Oct 2026 incomplete (data retrieved 2pm, Tue 6 Oct 2026)
A4: $ | B4: Sep 2026 | C4: Aug 2026 | D4: Change
A5: Current assets
A6: Cash at bank | B6: 149260 | C6: 192150 | D6: =B6-C6
A7: Trade debtors (unpaid invoices) | B7: 116800 | C7: 71290 | D7: =B7-C7
A8: Work in progress (unbilled project time) | B8: 99290 | C8: 77900 | D8: =B8-C8
A9: Prepayments | B9: 15000 | C9: 15000 | D9: =B9-C9
A10: Total current assets | B10: =SUM(B6:B9) | C10: =SUM(C6:C9) | D10: =B10-C10
A11: Office equipment | B11: 60200 | C11: 59000 | D11: =B11-C11
A12: Total assets | B12: =B10+B11 | C12: =C10+C11 | D12: =B12-C12
A13: Current liabilities
A14: Trade creditors (bills due next month) | B14: 8500 | C14: 6900 | D14: =B14-C14
A15: Employee leave provisions | B15: 122300 | C15: 121700 | D15: =B15-C15
A16: Income tax payable | B16: 56576 | C16: 50398 | D16: =B16-C16
A17: Total current liabilities | B17: =SUM(B14:B16) | C17: =SUM(C14:C16) | D17: =B17-C17
A18: Equipment finance | B18: 14600 | C18: 16300 | D18: =B18-C18
A19: Total liabilities | B19: =B17+B18 | C19: =C17+C18 | D19: =B19-C19
A20: Net assets | B20: =B12-B19 | C20: =C12-C19 | D20: =B20-C20
A21: Equity
A22: Share capital | B22: 20000 | C22: 20000 | D22: =B22-C22
A23: Retained earnings | B23: 218574 | C23: 200042 | D23: =B23-C23
A24: Total equity | B24: =SUM(B22:B23) | C24: =SUM(C22:C23) | D24: =B24-C24

Sheet Cash flow
A1: Cash flow, September 2026
A2: Sample Advisory Pty Ltd · SAMPLE DATA (invented) · The Fourth Sheet
A3: Data status: Sep 2026 locked · Aug 2026 locked · Oct 2026 incomplete (data retrieved 2pm, Tue 6 Oct 2026)
A4: $ | B4: Sep 2026 | C4: Aug 2026 | D4: Change
A5: Operating activities
A6: Receipts from customers (invoices paid) | B6: 64950 | C6: 137200 | D6: =B6-C6
A7: Payments to contractors and suppliers | B7: -32800 | C7: -31300 | D7: =B7-C7
A8: Payments to employees | B8: -69900 | C8: -69800 | D8: =B8-C8
A9: Interest paid | B9: -240 | C9: -250 | D9: =B9-C9
A10: Income tax paid | B10: 0 | C10: 0 | D10: =B10-C10
A11: Net cash from operating activities | B11: =SUM(B6:B10) | C11: =SUM(C6:C10) | D11: =B11-C11
A12: Investing activities
A13: Purchase of equipment | B13: -3200 | C13: 0 | D13: =B13-C13
A14: Net cash from investing activities | B14: =SUM(B13:B13) | C14: =SUM(C13:C13) | D14: =B14-C14
A15: Financing activities
A16: Equipment finance repaid | B16: -1700 | C16: -1700 | D16: =B16-C16
A17: Net cash from financing activities | B17: =SUM(B16:B16) | C17: =SUM(C16:C16) | D17: =B17-C17
A18: Net change in cash | B18: =B11+B14+B17 | C18: =C11+C14+C17 | D18: =B18-C18
A19: Cash at start of month | B19: 192150 | C19: 158000 | D19: =B19-C19
A20: Cash at end of month | B20: =B19+B18 | C20: =C19+C18 | D20: =B20-C20

Sheet Engagements
A1: Client engagements, September and August 2026
A2: Sample Advisory Pty Ltd · SAMPLE DATA (invented) · The Fourth Sheet
A3: Data status: Sep 2026 locked · Aug 2026 locked · Oct 2026 incomplete (data retrieved 2pm, Tue 6 Oct 2026)
A4: Consultant cost rate ($ per hour) | B4: 60
A6: Month | B6: Engagement | C6: Type | D6: Hours | E6: Revenue | F6: Billed | G6: Contractors | H6: Consultant time cost | I6: Contribution | J6: Margin %
A7: 2026-09 | B7: Agribusiness CFO support | C7: Retainer | D7: 70 | E7: 12000 | F7: 12000 | G7: 0 | H7: =D7*$B$4 | I7: =E7-G7-H7 | J7: =IF(E7=0,"",I7/E7)
A8: 2026-09 | B8: Construction firm finance | C8: Retainer | D8: 58 | E8: 9500 | F8: 9500 | G8: 0 | H8: =D8*$B$4 | I8: =E8-G8-H8 | J8: =IF(E8=0,"",I8/E8)
A9: 2026-09 | B9: Dental group reporting | C9: Retainer | D9: 44 | E9: 6800 | F9: 6800 | G9: 0 | H9: =D9*$B$4 | I9: =E9-G9-H9 | J9: =IF(E9=0,"",I9/E9)
A10: 2026-09 | B10: Excel for managers | C10: Training | D10: 30 | E10: 8800 | F10: 8800 | G10: 1500 | H10: =D10*$B$4 | I10: =E10-G10-H10 | J10: =IF(E10=0,"",I10/E10)
A11: 2026-09 | B11: Health charity board pack | C11: Project | D11: 64 | E11: 10560 | F11: 10560 | G11: 0 | H11: =D11*$B$4 | I11: =E11-G11-H11 | J11: =IF(E11=0,"",I11/E11)
A12: 2026-09 | B12: Hospitality payroll | C12: Retainer | D12: 36 | E12: 4200 | F12: 4200 | G12: 0 | H12: =D12*$B$4 | I12: =E12-G12-H12 | J12: =IF(E12=0,"",I12/E12)
A13: 2026-09 | B13: Logistics systems rollout | C13: Project | D13: 210 | E13: 36750 | F13: 30000 | G13: 4800 | H13: =D13*$B$4 | I13: =E13-G13-H13 | J13: =IF(E13=0,"",I13/E13)
A14: 2026-09 | B14: Manufacturer process mapping | C14: Project | D14: 120 | E14: 20400 | F14: 24000 | G14: 2200 | H14: =D14*$B$4 | I14: =E14-G14-H14 | J14: =IF(E14=0,"",I14/E14)
A15: 2026-09 | B15: Power BI basics | C15: Training | D15: 14 | E15: 4600 | F15: 4600 | G15: 0 | H15: =D15*$B$4 | I15: =E15-G15-H15 | J15: =IF(E15=0,"",I15/E15)
A16: 2026-09 | B16: Retail pricing review | C16: Project | D16: 96 | E16: 18240 | F16: 0 | G16: 0 | H16: =D16*$B$4 | I16: =E16-G16-H16 | J16: =IF(E16=0,"",I16/E16)
A17: 2026-08 | B17: Agribusiness CFO support | C17: Retainer | D17: 68 | E17: 12000 | F17: 12000 | G17: 0 | H17: =D17*$B$4 | I17: =E17-G17-H17 | J17: =IF(E17=0,"",I17/E17)
A18: 2026-08 | B18: Budgeting workshop | C18: Training | D18: 20 | E18: 6400 | F18: 6400 | G18: 900 | H18: =D18*$B$4 | I18: =E18-G18-H18 | J18: =IF(E18=0,"",I18/E18)
... A25: 2026-08 | B25: Retail pricing review | C25: Project | D25: 60 | E25: 11400 | F25: 0 | G25: 0 | H25: =D25*$B$4 | I25: =E25-G25-H25 | J25: =IF(E25=0,"",I25/E25)
A26: Total | D26: =SUM(D7:D25) | E26: =SUM(E7:E25) | F26: =SUM(F7:F25) | G26: =SUM(G7:G25) | H26: =SUM(H7:H25) | I26: =SUM(I7:I25)

Sheet Workings
A1: How each number is worked out
A2: Sample Advisory Pty Ltd · SAMPLE DATA (invented) · The Fourth Sheet
A3: Data status: Sep 2026 locked · Aug 2026 locked · Oct 2026 incomplete (data retrieved 2pm, Tue 6 Oct 2026)
A5: Consultant utilisation
A6: Billable hours ÷ hours available
B7: Sep 2026 | C7: Aug 2026
A8: Billable hours (timesheets) | B8: 742 | C8: 648
A9: Consultants | B9: 6 | C9: 6
A10: Working days | B10: 22 | C10: 20
A11: Hours per day | B11: 7.6 | C11: 7.6
A12: Hours available | B12: =B9*B10*B11 | C12: =C9*C10*C11
A13: Utilisation | B13: =B8/B12 | C13: =C8/C12
A16: Revenue per billable hour
A17: Revenue ÷ billable hours
B18: Sep 2026 | C18: Aug 2026
A19: Revenue | B19: 131850 | C19: 114640
A20: Billable hours | B20: 742 | C20: 648
A21: Revenue per hour | B21: =B19/B20 | C21: =C19/C20
A22: Retainers and training are fixed fees, so fewer hours on them raises the hourly figure.
A25: Cash tied up in work
A26: Work in progress + unpaid invoices at month end
B27: Sep 2026 | C27: Aug 2026
A28: Work in progress (project time not yet billed) | B28: 99290 | C28: 77900
A29: Unpaid client invoices | B29: 116800 | C29: 71290
A30: Total tied up | B30: =B28+B29 | C30: =C28+C29
A31: Milestone billing on the logistics and manufacturer projects landed at the end of September, so it moved from unbilled to unpaid.
A34: Power BI basics
A35: Contribution ÷ revenue for this engagement
B36: This engagement
A37: Revenue | B37: 4600
A38: Contractors | B38: 0
A39: Consultant hours | B39: 14
A40: Consultant cost rate ($/hour) | B40: 60
A41: Consultant time | B41: =-B39*B40
A42: Contribution | B42: =B37+B38+B41
A43: Margin | B43: =B42/B37
A46: Retail pricing review
A47: Contribution ÷ revenue for this engagement
B48: This engagement
A49: Revenue | B49: 18240
...

Sheet Assumptions
A1: Assumptions
A2: Sample Advisory Pty Ltd · SAMPLE DATA (invented) · The Fourth Sheet
A3: Data status: Sep 2026 locked · Aug 2026 locked · Oct 2026 incomplete (data retrieved 2pm, Tue 6 Oct 2026)
A5: The business
A6: What it is | B6: A Brisbane finance and operations consultancy: projects billed on milestones, monthly retainers and training. 6 consultants, 3 management and admin staff.
A7: Reporting month | B7: September 2026, compared with August 2026
A8: Financial year | B8: FY2027: 1 July 2026 to 30 June 2027
A10: Engagements (September)
A11: Projects | B11: hours worked at each project's rate; billed on milestones (unbilled time = work in progress)
A12: Retainers | B12: fixed monthly fee, billed monthly
A13: Training | B13: fixed fee, billed on delivery
A14: Engagements in September | B14: 10 (every one is in the Excel download and CSV)
A16: Costs
A17: Consultants | B17: 6 on salary: $46,500 a month incl. super
A18: Engagement costing rate | B18: $60/hour for consultant time
A19: Working days | B19: 20 in August (Ekka show holiday), 22 in September; 7.6 hours a day
A20: Income tax | B20: 25% of profit, provided monthly
A22: Cash and balance sheet
A23: Client payments | B23: each invoice is paid on its own date; unpaid invoices at month end = debtors
A24: Contractors | B24: paid the following month
A25: GST | B25: excluded throughout, for simplicity
A27: Checks (all passed)
A28: ✓ Every subtotal and total adds up
A29: ✓ Balance sheet balances: assets = liabilities + equity
A30: ✓ Cash flow ends at the cash in the bank
A31: ✓ Profit ties to the movement in retained earnings
A32: ✓ Every engagement's revenue adds up to the P&L
A33: ✓ Work in progress equals unbilled project time; debtors equal unpaid invoices
A35: Print check (done before this file was saved)
A36: ✓ The fourth sheet: 1 page, 100% scale, no block split
A37: ✓ Profit and loss: 1 page, 100% scale, no block split
A38: ✓ Balance sheet: 1 page, 100% scale, no block split
A39: ✓ Cash flow: 1 page, 100% scale, no block split
... A42: ✓ Assumptions: 2 pages, 100% scale, no block split
