Workbook

Sheet The fourth sheet
A1: The fourth sheet: September 2026 against August 2026
A2: Sample Electrical & Air Pty Ltd · SAMPLE DATA (invented) · The Fourth Sheet
A3: Data status: Sep 2026 locked · Aug 2026 locked · Oct 2026 incomplete (data retrieved 2pm, Tue 6 Oct 2026)
A5: Headline number | B5: Sep 2026 | C5: Aug 2026 | D5: Change
A6: Gross margin | B6: =Workings!B13 | C6: =Workings!C13 | D6: =B6-C6
A7: Cost to win a customer | B7: =Workings!B22 | C7: =Workings!C22 | D7: =B7-C7
A8: Technician time on jobs | B8: =Workings!B33 | C8: =Workings!C33 | D8: =B8-C8
A11: Margin on each installation job invoiced in September 2026
A12: Whole job, recognised when invoiced: revenue less materials, subcontractors and technician time at $68/hour. One 35.0% target for every job for now.
B13: Margin % | C13: Gross profit $
A14: Bulimba EV chargers | B14: =Workings!B47 | C14: =Workings!B46
A15: Milton office LED lighting | B15: =Workings!B60 | C15: =Workings!B59
A16: Chermside clinic cabling | B16: =Workings!B73 | C16: =Workings!B72
A17: West End cafe air-con | B17: =Workings!B86 | C17: =Workings!B85
A18: Carindale solar and battery | B18: =Workings!B99 | C18: =Workings!B98
A19: Wacol warehouse switchboard | B19: =Workings!B112 | C19: =Workings!B111
A20: Target | B20: 0.35

Sheet Profit and loss
A1: Profit and loss, September 2026
A2: Sample Electrical & Air Pty Ltd · SAMPLE DATA (invented) · The Fourth Sheet
A3: Data status: Sep 2026 locked · Aug 2026 locked · Oct 2026 incomplete (data retrieved 2pm, Tue 6 Oct 2026)
A4: $ | B4: Sep 2026 | C4: Aug 2026 | D4: Change
A5: Revenue
A6: Maintenance contracts (14) | B6: 40500 | C6: 40500 | D6: =B6-C6
A7: Installations (jobs) | B7: 130700 | C7: 109600 | D7: =B7-C7
A8: Call-outs and repairs | B8: 31137 | C8: 28907 | D8: =B8-C8
A9: Total revenue | B9: =SUM(B6:B8) | C9: =SUM(C6:C8) | D9: =B9-C9
A10: Cost of sales
A11: Materials | B11: -64860 | C11: -51530 | D11: =B11-C11
A12: Subcontractors | B12: -13200 | C12: -9300 | D12: =B12-C12
A13: Technician wages (incl. super) | B13: -54600 | C13: -54600 | D13: =B13-C13
A14: Total cost of sales | B14: =SUM(B11:B13) | C14: =SUM(C11:C13) | D14: =B14-C14
A15: Gross profit | B15: =B9+B14 | C15: =C9+C14 | D15: =B15-C15
A16: Operating expenses
A17: Office and admin wages | B17: -21900 | C17: -21900 | D17: =B17-C17
A18: Marketing | B18: -7600 | C18: -8400 | D18: =B18-C18
A19: Vehicles and fuel | B19: -8300 | C19: -7900 | D19: =B19-C19
A20: Rent and occupancy | B20: -7000 | C20: -7000 | D20: =B20-C20
A21: Insurance | B21: -3000 | C21: -3000 | D21: =B21-C21
A22: IT and software | B22: -2300 | C22: -2300 | D22: =B22-C22
A23: Other overheads | B23: -3900 | C23: -3600 | D23: =B23-C23
A24: Total operating expenses | B24: =SUM(B17:B23) | C24: =SUM(C17:C23) | D24: =B24-C24
A25: EBITDA | B25: =B15+B24 | C25: =C15+C24 | D25: =B25-C25
A26: Depreciation | B26: -4500 | C26: -4300 | D26: =B26-C26
A27: Interest | B27: -1080 | C27: -1100 | D27: =B27-C27
A28: Profit before tax | B28: =B25+B26+B27 | C28: =C25+C26+C27 | D28: =B28-C28
A29: Income tax provision (25%) | B29: -2524 | C29: -1019 | D29: =B29-C29
A30: Net profit after tax | B30: =B28+B29 | C30: =C28+C29 | D30: =B30-C30

Sheet Balance sheet
A1: Balance sheet at 30 September 2026
A2: Sample Electrical & Air Pty Ltd · SAMPLE DATA (invented) · The Fourth Sheet
A3: Data status: Sep 2026 locked · Aug 2026 locked · Oct 2026 incomplete (data retrieved 2pm, Tue 6 Oct 2026)
A4: $ | B4: Sep 2026 | C4: Aug 2026 | D4: Change
A5: Current assets
A6: Cash at bank | B6: 59746 | C6: 65263 | D6: =B6-C6
A7: Trade debtors (unpaid invoices) | B7: 151063 | C7: 129819 | D7: =B7-C7
A8: Materials on hand | B8: 66000 | C8: 66000 | D8: =B8-C8
A9: Prepayments | B9: 21000 | C9: 21000 | D9: =B9-C9
A10: Total current assets | B10: =SUM(B6:B9) | C10: =SUM(C6:C9) | D10: =B10-C10
A11: Vehicles and equipment | B11: 255200 | C11: 247700 | D11: =B11-C11
A12: Total assets | B12: =B10+B11 | C12: =C10+C11 | D12: =B12-C12
A13: Current liabilities
A14: Trade creditors (bills due next month) | B14: 78060 | C14: 60830 | D14: =B14-C14
A15: Employee leave provisions | B15: 106000 | C15: 105100 | D15: =B15-C15
A16: Income tax payable | B16: 35043 | C16: 32519 | D16: =B16-C16
A17: Total current liabilities | B17: =SUM(B14:B16) | C17: =SUM(C14:C16) | D17: =B17-C17
A18: Equipment finance | B18: 95000 | C18: 100000 | D18: =B18-C18
A19: Total liabilities | B19: =B17+B18 | C19: =C17+C18 | D19: =B19-C19
A20: Net assets | B20: =B12-B19 | C20: =C12-C19 | D20: =B20-C20
A21: Equity
A22: Share capital | B22: 10000 | C22: 10000 | D22: =B22-C22
A23: Retained earnings | B23: 228906 | C23: 221333 | D23: =B23-C23
A24: Total equity | B24: =SUM(B22:B23) | C24: =SUM(C22:C23) | D24: =B24-C24

Sheet Cash flow
A1: Cash flow, September 2026
A2: Sample Electrical & Air Pty Ltd · SAMPLE DATA (invented) · The Fourth Sheet
A3: Data status: Sep 2026 locked · Aug 2026 locked · Oct 2026 incomplete (data retrieved 2pm, Tue 6 Oct 2026)
A4: $ | B4: Sep 2026 | C4: Aug 2026 | D4: Change
A5: Operating activities
A6: Receipts from customers (invoices paid) | B6: 181093 | C6: 156273 | D6: =B6-C6
A7: Payments to suppliers | B7: -92930 | C7: -97510 | D7: =B7-C7
A8: Payments to employees | B8: -75600 | C8: -75400 | D8: =B8-C8
A9: Interest paid | B9: -1080 | C9: -1100 | D9: =B9-C9
A10: Income tax paid | B10: 0 | C10: 0 | D10: =B10-C10
A11: Net cash from operating activities | B11: =SUM(B6:B10) | C11: =SUM(C6:C10) | D11: =B11-C11
A12: Investing activities
A13: Purchase of vehicles and equipment | B13: -12000 | C13: 0 | D13: =B13-C13
A14: Net cash from investing activities | B14: =SUM(B13:B13) | C14: =SUM(C13:C13) | D14: =B14-C14
A15: Financing activities
A16: Equipment finance repaid | B16: -5000 | C16: -5000 | D16: =B16-C16
A17: Net cash from financing activities | B17: =SUM(B16:B16) | C17: =SUM(C16:C16) | D17: =B17-C17
A18: Net change in cash | B18: =B11+B14+B17 | C18: =C11+C14+C17 | D18: =B18-C18
A19: Cash at start of month | B19: 65263 | C19: 88000 | D19: =B19-C19
A20: Cash at end of month | B20: =B19+B18 | C20: =C19+C18 | D20: =B20-C20

Sheet Jobs
A1: Jobs, September and August 2026
A2: Sample Electrical & Air Pty Ltd · SAMPLE DATA (invented) · The Fourth Sheet
A3: Data status: Sep 2026 locked · Aug 2026 locked · Oct 2026 incomplete (data retrieved 2pm, Tue 6 Oct 2026)
A4: Technician cost rate ($ per hour) | B4: 68
A6: Month | B6: Job | C6: Type | D6: Invoiced | E6: Paid | F6: Revenue | G6: Materials | H6: Subcontractors | I6: Tech hours | J6: Labour cost | K6: Gross profit | L6: Margin %
A7: 2026-09 | B7: Call-out 1, September | C7: Call-out | D7: 46273 | E7: 46273 | F7: 589 | G7: 230 | H7: 0 | I7: 2 | J7: =I7*$B$4 | K7: =F7-G7-H7-J7 | L7: =IF(F7=0,"",K7/F7)
A8: 2026-09 | B8: Call-out 10, September | C8: Call-out | D8: 46282 | E8: 46284 | F8: 539 | G8: 80 | H8: 0 | I8: 3 | J8: =I8*$B$4 | K8: =F8-G8-H8-J8 | L8: =IF(F8=0,"",K8/F8)
A9: 2026-09 | B9: Call-out 11, September | C9: Call-out | D9: 46289 | E9: 46296 | F9: 526 | G9: 70 | H9: 0 | I9: 3 | J9: =I9*$B$4 | K9: =F9-G9-H9-J9 | L9: =IF(F9=0,"",K9/F9)
A10: 2026-09 | B10: Call-out 12, September | C10: Call-out | D10: 46282 | E10: 46289 | F10: 413 | G10: 150 | H10: 0 | I10: 1.5 | J10: =I10*$B$4 | K10: =F10-G10-H10-J10 | L10: =IF(F10=0,"",K10/F10)
A11: 2026-09 | B11: Call-out 13, September | C11: Call-out | D11: 46269 | E11: 46269 | F11: 775 | G11: 150 | H11: 0 | I11: 4 | J11: =I11*$B$4 | K11: =F11-G11-H11-J11 | L11: =IF(F11=0,"",K11/F11)
A12: 2026-09 | B12: Call-out 14, September | C12: Call-out | D12: 46269 | E12: 46269 | F12: 348 | G12: 100 | H12: 0 | I12: 1.5 | J12: =I12*$B$4 | K12: =F12-G12-H12-J12 | L12: =IF(F12=0,"",K12/F12)
A13: 2026-09 | B13: Call-out 15, September | C13: Call-out | D13: 46280 | E13: 46310 | F13: 775 | G13: 150 | H13: 0 | I13: 4 | J13: =I13*$B$4 | K13: =F13-G13-H13-J13 | L13: =IF(F13=0,"",K13/F13)
A14: 2026-09 | B14: Call-out 16, September | C14: Call-out | D14: 46266 | E14: 46273 | F14: 368 | G14: 60 | H14: 0 | I14: 2 | J14: =I14*$B$4 | K14: =F14-G14-H14-J14 | L14: =IF(F14=0,"",K14/F14)
A15: 2026-09 | B15: Call-out 17, September | C15: Call-out | D15: 46273 | E15: 46280 | F15: 526 | G15: 70 | H15: 0 | I15: 3 | J15: =I15*$B$4 | K15: =F15-G15-H15-J15 | L15: =IF(F15=0,"",K15/F15)
A16: 2026-09 | B16: Call-out 18, September | C16: Call-out | D16: 46271 | E16: 46271 | F16: 467 | G16: 80 | H16: 0 | I16: 2.5 | J16: =I16*$B$4 | K16: =F16-G16-H16-J16 | L16: =IF(F16=0,"",K16/F16)
A17: 2026-09 | B17: Call-out 19, September | C17: Call-out | D17: 46288 | E17: 46288 | F17: 589 | G17: 230 | H17: 0 | I17: 2 | J17: =I17*$B$4 | K17: =F17-G17-H17-J17 | L17: =IF(F17=0,"",K17/F17)
A18: 2026-09 | B18: Call-out 2, September | C18: Call-out | D18: 46280 | E18: 46280 | F18: 604 | G18: 130 | H18: 0 | I18: 3 | J18: =I18*$B$4 | K18: =F18-G18-H18-J18 | L18: =IF(F18=0,"",K18/F18)
... A167: 2026-08 | B167: Wynnum medical centre | C167: Maintenance contract | D167: 46235 | E167: 46260 | F167: 2200 | G167: 40 | H167: 0 | I167: 12 | J167: =I167*$B$4 | K167: =F167-G167-H167-J167 | L167: =IF(F167=0,"",K167/F167)
A168: Total | F168: =SUM(F7:F167) | G168: =SUM(G7:G167) | H168: =SUM(H7:H167) | I168: =SUM(I7:I167) | J168: =SUM(J7:J167) | K168: =SUM(K7:K167)

Sheet Workings
A1: How each number is worked out
A2: Sample Electrical & Air Pty Ltd · SAMPLE DATA (invented) · The Fourth Sheet
A3: Data status: Sep 2026 locked · Aug 2026 locked · Oct 2026 incomplete (data retrieved 2pm, Tue 6 Oct 2026)
A5: Gross margin
A6: Gross profit ÷ revenue
B7: Sep 2026 | C7: Aug 2026
A8: Revenue (every job invoiced in the month) | B8: 202337 | C8: 179007
A9: Materials | B9: -64860 | C9: -51530
A10: Subcontractors | B10: -13200 | C10: -9300
A11: Technician wages | B11: -54600 | C11: -54600
A12: Gross profit | B12: =B8+B9+B10+B11 | C12: =C8+C9+C10+C11
A13: Gross margin | B13: =B12/B8 | C13: =C12/C8
A14: Technicians are on salary, so a quiet month for jobs lowers the margin even if every job is priced well.
A17: Cost to win a customer
A18: Marketing spend ÷ new customers
B19: Sep 2026 | C19: Aug 2026
A20: Marketing spend | B20: 7600 | C20: 8400
A21: New customers (first job ever) | B21: 47 | C21: 41
A22: Cost per new customer | B22: =B20/B21 | C22: =C20/C21
A25: Technician time on jobs
A26: Hours charged to jobs ÷ hours available
B27: Sep 2026 | C27: Aug 2026
A28: Hours charged to jobs (timesheets) | B28: 752.5 | C28: 655
A29: Technicians | B29: 7 | C29: 7
A30: Working days | B30: 22 | C30: 20
A31: Hours per day | B31: 7.6 | C31: 7.6
A32: Hours available | B32: =B29*B30*B31 | C32: =C29*C30*C31
A33: Time on jobs | B33: =B28/B32 | C33: =C28/C32
A34: August had one fewer working day for the Ekka show holiday. The rest is travel, training, quoting and waiting time.
A37: Bulimba EV chargers
A38: Gross profit ÷ revenue for this job
B39: This job
A40: Revenue | B40: 9800
A41: Materials | B41: -3600
A42: Subcontractors | B42: 0
A43: Technician hours | B43: 26
A44: Technician cost rate ($/hour) | B44: 68
A45: Technician time | B45: =-B43*B44
A46: Gross profit | B46: =B40+B41+B42+B45
A47: Margin | B47: =B46/B40
...

Sheet Assumptions
A1: Assumptions
A2: Sample Electrical & Air Pty Ltd · SAMPLE DATA (invented) · The Fourth Sheet
A3: Data status: Sep 2026 locked · Aug 2026 locked · Oct 2026 incomplete (data retrieved 2pm, Tue 6 Oct 2026)
A5: The business
A6: What it is | B6: An electrical and air-conditioning contractor in Brisbane: maintenance contracts, installations and call-outs. 7 technicians, 3 office staff.
A7: Reporting month | B7: September 2026 (the last closed month), compared with August 2026
A8: Financial year | B8: FY2027: 1 July 2026 to 30 June 2027
A10: Jobs (September)
A11: Maintenance contracts | B11: 14 customers, invoiced on the 1st, paid in about 30 days
A12: Installations | B12: 6 named jobs, each with its own quote, materials, subcontractors and hours
A13: Call-outs | B13: 64 jobs at $145/hour plus materials marked up 30%
A14: Jobs in September | B14: 84 in total (every one is in the Excel download and CSV)
A16: Costs
A17: Technicians | B17: 7 on salary: $54,600 a month incl. super
A18: Job costing rate | B18: $68/hour for technician time charged to a job
A19: Working days | B19: 20 in August (Ekka show holiday), 22 in September; 7.6 hours a day
A20: Overheads | B20: set month by month, as shown in the P&L
A21: Income tax | B21: 25% of profit, provided monthly; next PAYG instalment due October
A23: Cash and balance sheet
A24: Customer payments | B24: each invoice is paid on its own date; unpaid invoices at month end = debtors
A25: Supplier bills | B25: materials and subcontractors are paid the following month
A26: Equipment finance | B26: $5,000 repaid each month
A27: New equipment | B27: a $12,000 trailer bought in September
A28: GST | B28: excluded throughout, for simplicity
A30: Checks (all passed)
A31: ✓ Every subtotal and total adds up
A32: ✓ Balance sheet balances: assets = liabilities + equity
A33: ✓ Cash flow ends at the cash in the bank
A34: ✓ Profit ties to the movement in retained earnings
A35: ✓ Every job's revenue, materials and subcontractors add up to the P&L
A36: ✓ Trade debtors equal the invoices still unpaid at month end
A38: Print check (done before this file was saved)
A39: ✓ The fourth sheet: 1 page, 100% scale, no block split
A40: ✓ Profit and loss: 1 page, 100% scale, no block split
A41: ✓ Balance sheet: 1 page, 100% scale, no block split
A42: ✓ Cash flow: 1 page, 100% scale, no block split
... A45: ✓ Assumptions: 2 pages, 100% scale, no block split
