Workbook
Name Called_back_within_2_working_hours_December: 'Report'!$B$9
Name Median_wait_December: 'Report'!$B$10
Name Enquiries_December: 'Report'!$B$11

Sheet Report
A1: How long do customers wait for a callback?
A2: Sample Electrical & Air Pty Ltd · SAMPLE DATA (invented) · The Fourth Sheet · Made with Python (openpyxl)
A3: Period: December 2025 · Data status: Nov 2025 locked · Dec 2025 locked · Oct 2026 incomplete (data retrieved 2pm, Tue 6 Oct 2026) · Generated 10 Oct 2026, 9:55pm
A5: In short: 70.6% called back within 2 working hours in December (target 80.0%); median wait 69 working minutes.
A6: Every customer enquiry (phone, web form, email) and how long until someone first called back, in working minutes. Every call-out job has the enquiry that booked it.
A8: Headline number | B8: Value | C8: Compared with
A9: Called back within 2 working hours, December | B9: =Workings!B10 | C9: target 80.0% · November 66.7%
A10: Median wait, December | B10: =Workings!B16 | C10: November 79 min (working minutes)
A11: Enquiries, December | B11: =Workings!B25 | C11: November 84
A13: Called back within 2 working hours, by channel, December 2025
B14: Called back within 2 working hours
A15: Phone | B15: =Workings!B37
A16: Web form | B16: =Workings!B45
A17: Email | B17: =Workings!B53
A27: Callbacks by month: every month is on the Data sheet.
A29: What it shows
A30: 70.6% of the 119 enquiries called back in December heard back within 2 working hours (target 80.0%), up from 66.7% in November. The median wait was 69 working minutes.
A32: What you'd do about it
A33: 11 more enquiries would have needed a faster callback to reach the 80.0% target. Email enquiries are the slowest: 60.0% within 2 working hours.

Sheet Workings
A1: How each number is worked out
A2: Sample Electrical & Air Pty Ltd · SAMPLE DATA (invented) · The Fourth Sheet · Made with Python (openpyxl)
A3: Period: December 2025 · Data status: Nov 2025 locked · Dec 2025 locked · Oct 2026 incomplete (data retrieved 2pm, Tue 6 Oct 2026) · Generated 10 Oct 2026, 9:55pm
A5: Callbacks within 2 working hours, December and November
A6: Within 2 working hours ÷ called back
B7: Dec 25 | C7: Nov 25
A8: Called back | B8: 119 | C8: 84
A9: Within 2 working hours | B9: 84 | C9: 56
A10: Share | B10: =B9/B8 | C10: =C9/C8
A13: Median wait for a callback, December and November
A14: The middle wait, in working minutes
B15: Dec 25 | C15: Nov 25
A16: Median wait (working minutes) | B16: 69 | C16: 79
A17: Enquiries called back | B17: 119 | C17: 84
A18: Working minutes: 8:30am to 5pm on working days.
A21: Callbacks, Dec 25
A22: Enquiries called back within 2 working hours ÷ enquiries called back
B23: Dec 25
A24: Enquiries | B24: 119
A25: Called back | B25: 119
A26: Called back within 2 working hours | B26: 84
A27: Share within 2 working hours | B27: =B26/B25
A28: Median wait (working minutes) | B28: 69
A29: Working minutes only: 8:30am to 5pm on working days. The median is the middle wait when every callback is lined up.
A32: Phone: callbacks, December 2025
A33: Within 2 working hours ÷ called back
B34: Dec 2025
A35: Called back | B35: 74
A36: Within 2 working hours | B36: 54
A37: Share | B37: =B36/B35
A40: Web form: callbacks, December 2025
A41: Within 2 working hours ÷ called back
B42: Dec 2025
A43: Called back | B43: 30
A44: Within 2 working hours | B44: 21
A45: Share | B45: =B44/B43
A48: Email: callbacks, December 2025
A49: Within 2 working hours ÷ called back
B50: Dec 2025
A51: Called back | B51: 15
...

Sheet Chart lines
A1: Points for the target and break-even lines drawn on the charts (hidden sheet; edit the values on the chart's own sheet).
A3: Report: Called back within 2 working hours, by channel, December 2025: Target 80.0%
B4: 0.8 | C4: 0
B5: 0.8 | C5: 1

Sheet Data
A1: Data
A2: Sample Electrical & Air Pty Ltd · SAMPLE DATA (invented) · The Fourth Sheet · Made with Python (openpyxl)
A3: Period: December 2025 · Data status: Nov 2025 locked · Dec 2025 locked · Oct 2026 incomplete (data retrieved 2pm, Tue 6 Oct 2026) · Generated 10 Oct 2026, 9:55pm
A5: Month | B5: Status | C5: Enquiries | D5: Called back | E5: Within 2 working hours | F5: Share within target | G5: Median wait (min)
A6: Oct 24 | B6: Locked | C6: 96 | D6: 96 | E6: 83 | F6: =IF(D6=0,"",E6/D6) | G6: 40
A7: Nov 24 | B7: Locked | C7: 102 | D7: 102 | E7: 87 | F7: =IF(D7=0,"",E7/D7) | G7: 36
A8: Dec 24 | B8: Locked | C8: 121 | D8: 121 | E8: 100 | F8: =IF(D8=0,"",E8/D8) | G8: 38
A9: Jan 25 | B9: Locked | C9: 117 | D9: 117 | E9: 93 | F9: =IF(D9=0,"",E9/D9) | G9: 44
A10: Feb 25 | B10: Locked | C10: 97 | D10: 97 | E10: 72 | F10: =IF(D10=0,"",E10/D10) | G10: 51
A11: Mar 25 | B11: Locked | C11: 96 | D11: 96 | E11: 70 | F11: =IF(D11=0,"",E11/D11) | G11: 66
A12: Apr 25 | B12: Locked | C12: 90 | D12: 90 | E12: 64 | F12: =IF(D12=0,"",E12/D12) | G12: 71
A13: May 25 | B13: Locked | C13: 96 | D13: 96 | E13: 71 | F13: =IF(D13=0,"",E13/D13) | G13: 55
A14: Jun 25 | B14: Locked | C14: 94 | D14: 94 | E14: 64 | F14: =IF(D14=0,"",E14/D14) | G14: 72
A15: Jul 25 | B15: Locked | C15: 96 | D15: 96 | E15: 64 | F15: =IF(D15=0,"",E15/D15) | G15: 67
A16: Aug 25 | B16: Locked | C16: 98 | D16: 98 | E16: 65 | F16: =IF(D16=0,"",E16/D16) | G16: 76
A17: Sep 25 | B17: Locked | C17: 109 | D17: 109 | E17: 76 | F17: =IF(D17=0,"",E17/D17) | G17: 82
... A20: Dec 25 | B20: Locked | C20: 119 | D20: 119 | E20: 84 | F20: =IF(D20=0,"",E20/D20) | G20: 69
