Workbook
Name Trades_March_against_March_last_year: 'Report'!$B$16
Name Trades_Year_to_date_Jul_to_Mar_2026: 'Report'!$B$17
Name Trades_Gross_margin_year_to_date: 'Report'!$B$18
Name Trades_March_against_March_last_year_2: 'Report'!$B$28
Name Trades_Year_to_date_Jul_to_Mar_2026_2: 'Report'!$B$29
Name Trades_Gross_margin_year_to_date_2: 'Report'!$B$30
Name Trades_March_against_March_last_year_3: 'Report'!$B$40
Name Trades_Year_to_date_Jul_to_Mar_2026_3: 'Report'!$B$41
Name Trades_Gross_margin_year_to_date_3: 'Report'!$B$42
Name Trades_March_against_March_last_year_4: 'Report'!$B$52
Name Trades_Year_to_date_Jul_to_Mar_2026_4: 'Report'!$B$53
Name Trades_Gross_margin_year_to_date_4: 'Report'!$B$54

Sheet Report
A1: Which products and services are growing?
A2: Sample Electrical & Air Pty Ltd · SAMPLE DATA (invented) · The Fourth Sheet · Made with Python (openpyxl)
A3: Period: March 2026 · Data status: Feb 2026 locked · Mar 2026 locked · Oct 2026 incomplete (data retrieved 2pm, Tue 6 Oct 2026) · Generated 8 Oct 2026, 9:35am
A5: Revenue, gross margin and growth (year on year) by product or service line over 24 months. Pick a line and every number, chart and note follows it.
A7: Trades
A8: From gross margin to profit
A9: March's jobs made $68,158 gross margin (35.6%). Technician time not charged to jobs took ($1,092) and overheads $59,200, leaving $10,050 profit before tax (5.2% of revenue). To cover overheads, jobs need a 30.3% gross margin on average. (Workings sheet: "From gross margin to profit".)
A11: Gross margin, not profit
A12: Gross margin is not profit. Job gross margin = revenue less materials, subcontractors and technician time charged to the job at $68 an hour (wages and all on-costs). Not included: technician time not charged to any job (travel, training, waiting), and overheads (office wages, marketing, vehicles, rent, insurance, IT, depreciation, interest). Profit is what's left after those. Wages always include all on-costs: super, payroll tax, workers' compensation insurance and leave.
A14: Line: All
A15: Headline number | B15: Value | C15: Compared with
A16: March against March last year | B16: =Workings!B27 | C16: $191,500 against $135,082
A17: Year to date (Jul to Mar 2026) | B17: =Workings!B35 | C17: same period last year: not in the data
A18: Gross margin, year to date | B18: =Workings!B43 | C18: $536,342 before overheads
A20: What it shows
A21: Revenue is $1,445,594 this financial year to date (Jul to Mar 2026). Maintenance contracts make the highest gross margin (59.5%); Installations the lowest (27.7%). The business needs 30.3% gross margin just to cover overheads.
A23: What you'd do about it
A24: Installations: 27.7% gross margin, 7.3 points under the 35.0% target: about $66,607 on $907,100 of revenue this financial year to date. It's below the 30.3% needed to cover overheads, too. Maintenance contracts: 59.5% gross margin, 24.5 points over the 35.0% target ($77,852 ahead on $317,800 this financial year to date).
A26: Line: Maintenance contracts
A27: Headline number | B27: Value | C27: Compared with
A28: March against March last year | B28: =Workings!B51 | C28: $37,500 against $27,930
A29: Year to date (Jul to Mar 2026) | B29: =Workings!B59 | C29: same period last year: not in the data
A30: Gross margin, year to date | B30: =Workings!B67 | C30: $189,082 before overheads
A32: What it shows
A33: Maintenance contracts brought in $317,800 this financial year to date, at a 59.5% gross margin (above the 37.1% overall).
A35: What you'd do about it
A36: Maintenance contracts: 59.5% gross margin, 24.5 points over the 35.0% target ($77,852 ahead on $317,800 this financial year to date).
A38: Line: Installations
A39: Headline number | B39: Value | C39: Compared with
A40: March against March last year | B40: =Workings!B75 | C40: $129,400 against $86,100
A41: Year to date (Jul to Mar 2026) | B41: =Workings!B83 | C41: same period last year: not in the data
A42: Gross margin, year to date | B42: =Workings!B91 | C42: $250,878 before overheads
A44: What it shows
A45: Installations brought in $907,100 this financial year to date, at a 27.7% gross margin (below the 37.1% overall).
A47: What you'd do about it
A48: Installations: 27.7% gross margin, 7.3 points under the 35.0% target: about $66,607 on $907,100 of revenue this financial year to date. It's below the 30.3% needed to cover overheads, too.
A50: Line: Call-outs and repairs
A51: Headline number | B51: Value | C51: Compared with
A52: March against March last year | B52: =Workings!B99 | C52: $24,600 against $21,052
A53: Year to date (Jul to Mar 2026) | B53: =Workings!B107 | C53: same period last year: not in the data
...

Sheet Workings
A1: How each number is worked out
A2: Sample Electrical & Air Pty Ltd · SAMPLE DATA (invented) · The Fourth Sheet · Made with Python (openpyxl)
A3: Period: March 2026 · Data status: Feb 2026 locked · Mar 2026 locked · Oct 2026 incomplete (data retrieved 2pm, Tue 6 Oct 2026) · Generated 8 Oct 2026, 9:35am
A5: Trades: From gross margin to profit, March 2026
A6: Gross margin on the work − time not charged − overheads = profit before tax
B7: Mar 2026
A8: Gross margin on jobs | B8: 68158
A9: Technician wages and on-costs | B9: 54600
A10: Technician time charged to jobs (at cost) | B10: 55692
A11: Technician time not charged to jobs | B11: =B9-B10
A12: Gross profit (the P&L) | B12: =B8-B11
A13: Overheads (operating expenses, depreciation, interest) | B13: 59200
A14: Profit before tax (the P&L) | B14: =B12-B13
A15: Revenue | B15: 191500
A16: Gross margin on jobs, % | B16: =B8/B15
A17: Profit before tax, % of revenue | B17: =B14/B15
A18: Gross margin jobs need just to cover overheads and time not charged | B18: =(B11+B13)/B15
A19: Ties to the March 2026 P&L (locked). Wages always include all on-costs: super, payroll tax, workers' compensation insurance and leave.
A22: Trades, all lines: March against March last year
A23: March 2026 ÷ March 2025 − 1 (year on year)
B24: Mar
A25: Revenue, Mar 2026 | B25: 191500
A26: Revenue, Mar 2025 | B26: 135082
A27: Growth | B27: =B25/B26-1
A30: Trades, all lines: year to date
A31: Financial year to date. Not available: the data starts October 2024.
B32: Year to date
A33: Revenue, year to date (Jul to Mar 2026) | B33: 1445594
A34: Gross margin, year to date | B34: 536342
A35: Gross margin %, year to date | B35: =B34/B33
A38: Trades, all lines: year to date
A39: Financial year to date. Not available: the data starts October 2024.
B40: Year to date
A41: Revenue, year to date (Jul to Mar 2026) | B41: 1445594
A42: Gross margin, year to date | B42: 536342
A43: Gross margin %, year to date | B43: =B42/B41
A46: Trades, Maintenance contracts: March against March last year
A47: March 2026 ÷ March 2025 − 1 (year on year)
B48: Mar
A49: Revenue, Mar 2026 | B49: 37500
...

Sheet Data Trades
A1: Data Trades
A2: Sample Electrical & Air Pty Ltd · SAMPLE DATA (invented) · The Fourth Sheet · Made with Python (openpyxl)
A3: Period: March 2026 · Data status: Feb 2026 locked · Mar 2026 locked · Oct 2026 incomplete (data retrieved 2pm, Tue 6 Oct 2026) · Generated 8 Oct 2026, 9:35am
A5: Line | B5: Month | C5: Status | D5: Revenue | E5: Direct cost | F5: Gross margin | G5: Gross margin %
A6: All | B6: Oct 24 | C6: Locked | D6: 171009 | E6: 114334 | F6: =D6-E6 | G6: =IF(D6=0,"",F6/D6)
A7: All | B7: Nov 24 | C7: Locked | D7: 179474 | E7: 113016 | F7: =D7-E7 | G7: =IF(D7=0,"",F7/D7)
A8: All | B8: Dec 24 | C8: Locked | D8: 143156 | E8: 85316 | F8: =D8-E8 | G8: =IF(D8=0,"",F8/D8)
A9: All | B9: Jan 25 | C9: Locked | D9: 140909 | E9: 80742 | F9: =D9-E9 | G9: =IF(D9=0,"",F9/D9)
A10: All | B10: Feb 25 | C10: Locked | D10: 160943 | E10: 102348 | F10: =D10-E10 | G10: =IF(D10=0,"",F10/D10)
A11: All | B11: Mar 25 | C11: Locked | D11: 135082 | E11: 85752 | F11: =D11-E11 | G11: =IF(D11=0,"",F11/D11)
A12: All | B12: Apr 25 | C12: Locked | D12: 124705 | E12: 76808 | F12: =D12-E12 | G12: =IF(D12=0,"",F12/D12)
A13: All | B13: May 25 | C13: Locked | D13: 129816 | E13: 83700 | F13: =D13-E13 | G13: =IF(D13=0,"",F13/D13)
A14: All | B14: Jun 25 | C14: Locked | D14: 164113 | E14: 97584 | F14: =D14-E14 | G14: =IF(D14=0,"",F14/D14)
A15: All | B15: Jul 25 | C15: Locked | D15: 186760 | E15: 120326 | F15: =D15-E15 | G15: =IF(D15=0,"",F15/D15)
A16: All | B16: Aug 25 | C16: Locked | D16: 139164 | E16: 78258 | F16: =D16-E16 | G16: =IF(D16=0,"",F16/D16)
A17: All | B17: Sep 25 | C17: Locked | D17: 128255 | E17: 80054 | F17: =D17-E17 | G17: =IF(D17=0,"",F17/D17)
... A77: Call-outs and repairs | B77: Mar 26 | C77: Locked | D77: 24600 | E77: 13894 | F77: =D77-E77 | G77: =IF(D77=0,"",F77/D77)

Sheet Year to date Trades
A1: Year to date Trades
A2: Sample Electrical & Air Pty Ltd · SAMPLE DATA (invented) · The Fourth Sheet · Made with Python (openpyxl)
A3: Period: March 2026 · Data status: Feb 2026 locked · Mar 2026 locked · Oct 2026 incomplete (data retrieved 2pm, Tue 6 Oct 2026) · Generated 8 Oct 2026, 9:35am
A5: Line | B5: Year to date | C5: Same period last year | D5: Growth | E5: Gross margin $ | F5: Gross margin %
A6: Maintenance contracts | B6: 317800 | D6: =IF(C6=0,"",B6/C6-1) | E6: 189082 | F6: =IF(B6=0,"",E6/B6)
A7: Installations | B7: 907100 | D7: =IF(C7=0,"",B7/C7-1) | E7: 250878 | F7: =IF(B7=0,"",E7/B7)
A8: Call-outs and repairs | B8: 220694 | D8: =IF(C8=0,"",B8/C8-1) | E8: 96382 | F8: =IF(B8=0,"",E8/B8)
A9: Total | B9: 1445594 | D9: =IF(C9=0,"",B9/C9-1) | E9: 536342 | F9: =IF(B9=0,"",E9/B9)
